<?xml version="1.0" ?>

<robot name="robot" xmlns:xacro="http://www.ros.org/wiki/xacro" >
	
	<xacro:property name="hbaza" value="${0.2}"/>
	<xacro:property name="params" value="${load_yaml('parametryDH.yaml')}"/>
	<xacro:property name="zmienne" value="${load_yaml('parametry.yaml')}"/>

	<link name="baza">
		<visual>
			<origin xyz="0 0 ${params['czlon1']['wysokosc']/2}" rpy="0 0 0"/>
			<material name="blue">
				<color rgba="0 0 0.8 0.5"/>
			</material>
			<geometry>
				<cylinder length="${params['czlon1']['wysokosc']+0.1}" radius="${zmienne['baza']['promien']}"/>
			</geometry>
		</visual>
	</link>
	<link name="czlon1">
		<visual>
			<origin xyz="${params['czlon2']['x']} 0 ${params['czlon2']['z']}" rpy="0 0 0"/>
			<material name="red">
				<color rgba="1 0 0 0.5"/>
			</material>
			<geometry>
				<box size= "${params['czlon2']['dlugosc']+0.1} 0.1 ${params['czlon2']['wysokosc']+0.1}"/>
			</geometry>
		</visual>
	</link>
	<joint name="poloczenie-baza-czlon1" type="revolute">
		<origin xyz="${params['czlon1']['xyz']}" rpy="${params['czlon1']['rpy']}"/>
		<parent link="baza"/>
		<child link="czlon1" />
		<axis xyz="0 0 1"/>
		<limit upper="3.14" lower="-3.14" effort="10" velocity="2" />  

	</joint>
	<link name="czlon2">
		<visual>
			<origin xyz="${params['czlon3']['x']} 0 ${params['czlon3']['z']}" rpy="0 0 0"/>
			<material name="red">
				<color rgba="1 0 0 0.5"/>
			</material>
			<geometry>
				<box size= "${params['czlon3']['dlugosc']+0.1} 0.1 ${params['czlon3']['wysokosc']+0.1}"/>
			</geometry>
		</visual>
	</link>
	<joint name="poloczenie-czlon1-czlon2" type="revolute">
		<origin xyz="${params['czlon2']['xyz']}" rpy="${params['czlon2']['rpy']}"/>
		<parent link="czlon1"/>
		<child link="czlon2" />
		<axis xyz="0 0 1"/>
		<limit upper="0" lower="-3.14" effort="10" velocity="2" />  
	</joint>
	<link name="czlon3">
		<visual>
			<origin xyz="${zmienne['czlon3']['dlugosc']/2}  0 0" rpy="0 0 0"/>
			<material name="red">
				<color rgba="1 0 0 0.5"/>
			</material>
			<geometry>
				<box size= "${zmienne['czlon3']['dlugosc']} ${zmienne['czlon3']['szerokosc']} ${zmienne['czlon3']['wysokosc']}"/>
			</geometry>
		</visual>
	</link>
	<joint name="poloczenie-czlon2-czlon3" type="revolute">
		<origin xyz="${params['czlon3']['xyz']}" rpy="${params['czlon3']['rpy']}"/>
		<parent link="czlon2"/>
		<child link="czlon3" />
		<axis xyz="0 0 1"/>
		<limit upper="3.14" lower="-3.14" effort="10" velocity="2" />  
	</joint>
	
		

</robot>
